Workbook

Sheet README
A1: 인귀 데이터 테이블 초안 (10/29, 김현호, SILENT 양식 ID로 개편)
A2: 모든 수치는 제안입니다. 전투 기획서·코어 기획서와 같은 값을 씁니다. 시트 하나 = CSV 하나(시트 이름.csv, UTF-8).
A4: 규칙 | B4: 내용
A5: 시트 형식 (SILENT와 같음) | B5: 1행 규칙(그 시트만의 규칙), 2행 기능, 3행 역할, 4행 의도, 5행 비고(코드가 읽지 않는 열), 6행 열 이름, 7행부터 데이터. 데이터 아래 빈 줄 뒤의 예시는 내보내지 않음
A6: 1열 ID | B6: 숫자. 시트마다 정해진 구간 안에서 차례로 매김(REGISTRY IDRange). 구간이 서로 겹치지 않아 파일 전체에서 같은 번호가 두 번 나오지 않음. 지운 번호는 다시 쓰지 않음. 절대 중복 금지
A7: 2열 Name | B7: 한국어 설명. 겹쳐도 되고 코드가 읽지 않음. 화면에 보이는 이름은 TextID로 String 시트를 가리킴
A8: 참조 | B8: 다른 시트는 숫자 ID로만 가리킴 (UnitID, OwnerID, AttackIDs, StartWeapon, SkillID, WeaponID, StateID, NextStage, StageID, TextID, 스폰 JSON code). 여러 개면 | 로 구분 (5001|5002|5003)
A9: 겹치면 안 되는 문자열 | B9: State.Key(애니메이터 상태 이름) 하나. 나머지 문자열 키는 없음
A10: 정해진 단어 | B10: 코드가 읽는 단어 값은 영어로 고정: Type(Player, Monster, Boss), AIType(MELEE, CHARGER), ExecuteType(KILL), Acquire(START, STORY), UnlockType(ROOM_LEDGER), Effect(CUT_BIND)
A11: Y / N | B11: Active(N이면 그 행을 읽지 않음), Dodgeable, SuperArmor, HangAuto, InGstar, State의 Common·Player·Monster·Boss·Required, REGISTRY Required
A12: 자료형·단위 | B12: 모두 정수. 비율·확률은 만분율(10000 = 100%), 시간 ms, 거리·속도 타일×100 (300 = 3타일)
A13: 스탯 곡선 | B13: 몬스터 값 = Base + Delta × Tier (StatCurve 시트, 계산용이라 내보내지 않음)
A15: ID 구간 | B15: 시트 | C15: 내용
A16: 1001~ | B16: UnitStat | C16: 플레이어·몬스터·보스 공통 스탯 (HP, ATK, DEF, 회피율, 치명타, 체세, 이동)
A17: 2001~ | B17: Player | C17: 스태미나·구르기·피격·약초 등 플레이어 전용 (UnitID → UnitStat, StartWeapon → Weapon)
A18: 3001~ | B18: Monster | C18: AI·시야·체세 회복·해체 방식 (UnitID → UnitStat, AttackIDs → Attack)
A19: 4001~ | B19: Boss | C19: 페이즈 한 행씩. 같은 보스는 UnitID가 같음 (AttackIDs → Attack)
A20: 5001~ | B20: Attack | C20: 공격별 배율·체세 피해·타이밍·회피 가능 여부 (OwnerID → UnitStat, StateID → State)
A21: 6001~ | B21: Weapon | C21: 무기 (지스타는 발골칼 1개. AttackIDs → Attack, SkillID → Skill)
A22: 7001~ | B22: Skill | C22: 스킬 (결박 가르기, 쿨타임만. WeaponID → Weapon, AttackID → Attack)
A23: 8001~ | B23: Stage | C23: 스테이지 순서·BGM·스폰 JSON (NextStage → Stage, 스폰 JSON code → Monster)
A24: 9001~ | B24: StageLayer | C24: 스테이지별 배경 레이어·패럴랙스 (StageID → Stage)
A25: 10001~ | B25: State | C25: 공통 상태 목록과 유닛별 사용 여부
A26: 11001~ | B26: REGISTRY | C26: 시트 목록·부모·ID 구간·읽는 순서. 로더가 맨 먼저 읽음 (CSV로 내보냄)
A27: 30001~ | B27: String | C27: 표시 텍스트 (한국어 우선, EN 칸 예비)
A29: 내보내지 않는 탭 | B29: 내용
A30: README | B30: 이 설명
A31: Reference | B31: 시트 간 참조 구조(매트릭스·참조 목록·읽는 순서). 열을 추가하면 여기와 REGISTRY를 같이 고칠 것
A32: StatCurve | B32: 등급별 선형 스탯 + 그래프. UnitStat 몬스터 행이 수식으로 가져감
A33: Balance | B33: 밸런스 계산기: 공격력·치명타와 회피율을 넣은 기대 데미지, 처치 타수, 버티는 횟수와 그래프 (UnitStat, Attack, Boss를 ID로 참조)
A35: ID 바꾸기 전 → 후 (10/29) | B35: PL_001→1001, MON_001~004→1002~1005, BOSS_001→1006, PLAYER_001→2001, MON(몬스터 행)→3001~3004, BOSS_001_P1·P2→4001·4002, PL_ATK_1~BOSS_SK1→5001~5016, WPN_001~003→6001~6003, SKL_001→7001, ST_01~04→8001~8004, ST_01_L0~ST_04_L1→9001~9015, Idle~Acquire→10001~10018, 문자열 키→30001~30026

Sheet Reference
A1: 데이터 테이블 참조 구조 (10/29 숫자 ID 기준)
A2: 가로줄 시트가 세로줄 시트를 참조합니다. 칸 안의 글자 = 참조할 때 쓰는 열 이름(값은 상대 시트의 숫자 ID). 빈칸 = 참조 없음. 시트 목록·부모·읽는 순서의 원본은 REGISTRY 탭.
A4: 참조하는 시트 ↓ / 참조되는 시트 → | B4: UnitStat | C4: Player | D4: Monster | E4: Boss | F4: Attack | G4: Weapon | H4: Skill | I4: State | J4: StatCurve | K4: Stage | L4: StageLayer | M4: String | N4: 스폰 JSON
A5: UnitStat | J5: Tier | M5: TextID
A6: Player | B6: UnitID | G6: StartWeapon
A7: Monster | B7: UnitID | F7: AttackIDs
A8: Boss | B8: UnitID | F8: AttackIDs
A9: Attack | B9: OwnerID | I9: StateID | M9: TextID
A10: Weapon | F10: AttackIDs | H10: SkillID | M10: TextID
A11: Skill | F11: AttackID | G11: WeaponID | M11: TextID
A12: State
A13: StatCurve
A14: Stage | K14: NextStage | M14: TextID | N14: SpawnFile
A15: StageLayer | K15: StageID
A16: String
A17: 스폰 JSON | D17: code
A18: 참조되는 횟수 | B18: 4 | C18: 0 | D18: 1 | E18: 0 | F18: 4 | G18: 2 | H18: 1 | I18: 1 | J18: 1 | K18: 2 | L18: 0 | M18: 5 | N18: 1
A20: 참조 목록 (열 단위)
A21: 참조하는 시트 | B21: 열 | C21: → 참조되는 시트 | D21: 키 열 | E21: 형식 | F21: 예시
A22: UnitStat | B22: Tier | C22: StatCurve | D22: Tier | E22: 단일 | F22: 1003(지게귀) Tier 2 → HP 50
A23: UnitStat | B23: TextID | C23: String | D23: ID | E23: 단일 | F23: 30001 → 막손
A24: Player | B24: UnitID | C24: UnitStat | D24: ID | E24: 단일 | F24: 1001
A25: Player | B25: StartWeapon | C25: Weapon | D25: ID | E25: 단일 | F25: 6001
A26: Monster | B26: UnitID | C26: UnitStat | D26: ID | E26: 단일 | F26: 1002
A27: Monster | B27: AttackIDs | C27: Attack | D27: ID | E27: | 목록 | F27: 5007|5008
A28: Boss | B28: UnitID | C28: UnitStat | D28: ID | E28: 단일 | F28: 1006
A29: Boss | B29: AttackIDs | C29: Attack | D29: ID | E29: | 목록 | F29: 5013|5014|5015
A30: Attack | B30: OwnerID | C30: UnitStat | D30: ID | E30: 단일 | F30: 1001
A31: Attack | B31: StateID | C31: State | D31: ID | E31: 단일 | F31: 10004 (Attack1)
A32: Attack | B32: TextID | C32: String | D32: ID | E32: 단일 | F32: 30015
A33: Weapon | B33: AttackIDs | C33: Attack | D33: ID | E33: | 목록 | F33: 5001|5002|5003|5004
A34: Weapon | B34: SkillID | C34: Skill | D34: ID | E34: 단일 | F34: 7001
A35: Skill | B35: WeaponID | C35: Weapon | D35: ID | E35: 단일 | F35: 6001
A36: Skill | B36: AttackID | C36: Attack | D36: ID | E36: 단일 | F36: 5006
A37: Stage | B37: NextStage | C37: Stage | D37: ID | E37: 단일(자기 참조) | F37: 8001 → 8002
A38: Stage | B38: SpawnFile | C38: 스폰 JSON | D38: 파일 경로 | E38: 단일 | F38: spawn/8001.json
A39: StageLayer | B39: StageID | C39: Stage | D39: ID | E39: 단일 | F39: 8001
A40: 스폰 JSON | B40: code | C40: Monster | D40: ID | E40: 단일 | F40: 3001
A41: *TextID | B41: TextID | C41: String | D41: ID | E41: 단일 | F41: Stage·Weapon·Skill·Attack·UnitStat 공통
A44: 읽는 순서 (참조되는 쪽을 먼저 불러오기, REGISTRY LoadOrder와 같음)
...

Sheet REGISTRY
A1: 규칙 | B1: 한 행 = 시트 하나. Parent·ParentKey는 이 시트 행이 매달리는 상위 시트와 그 열, Uses는 라이브러리처럼 참조하는 시트. Active = N이면 그 시트를 읽지 않는다.
A2: 기능 | B2: 시트 목록, 계층, ID 구간, 읽는 순서.
A3: 역할 | B3: 로더가 맨 먼저 읽는다.
A4: 의도 | B4: 시트를 모듈처럼 넣고 빼기 위해.
A5: 비고 | B5: Name, IDRange
A6: ID | B6: Name | C6: Sheet | D6: Parent | E6: ParentKey | F6: Uses | G6: IDRange | H6: LoadOrder | I6: Required | J6: Active
A7: 11001 | B7: 모듈 목록 | C7: REGISTRY | D7: - | E7: - | F7: - | G7: 11001~ | H7: 0 | I7: Y | J7: Y
A8: 11002 | B8: 표시 텍스트 | C8: String | D8: - | E8: - | F8: - | G8: 30001~ | H8: 1 | I8: Y | J8: Y
A9: 11003 | B9: 상태 | C9: State | D9: - | E9: - | F9: - | G9: 10001~ | H9: 1 | I9: Y | J9: Y
A10: 11004 | B10: 유닛 스탯 | C10: UnitStat | D10: - | E10: - | F10: String | G10: 1001~ | H10: 2 | I10: Y | J10: Y
A11: 11005 | B11: 공격 | C11: Attack | D11: UnitStat | E11: OwnerID | F11: State, String | G11: 5001~ | H11: 3 | I11: Y | J11: Y
A12: 11006 | B12: 스킬 | C12: Skill | D12: Weapon | E12: WeaponID | F12: Attack, String | G12: 7001~ | H12: 4 | I12: Y | J12: Y
A13: 11007 | B13: 무기 | C13: Weapon | D13: - | E13: - | F13: Attack, Skill, String | G13: 6001~ | H13: 4 | I13: Y | J13: Y
A14: 11008 | B14: 플레이어 | C14: Player | D14: UnitStat | E14: UnitID | F14: Weapon | G14: 2001~ | H14: 5 | I14: Y | J14: Y
A15: 11009 | B15: 몬스터 | C15: Monster | D15: UnitStat | E15: UnitID | F15: Attack | G15: 3001~ | H15: 5 | I15: Y | J15: Y
A16: 11010 | B16: 보스 페이즈 | C16: Boss | D16: UnitStat | E16: UnitID | F16: Attack | G16: 4001~ | H16: 5 | I16: Y | J16: Y
A17: 11011 | B17: 스테이지 | C17: Stage | D17: - | E17: - | F17: String, Monster(스폰 JSON) | G17: 8001~ | H17: 6 | I17: Y | J17: Y
A18: 11012 | B18: 배경 레이어 | C18: StageLayer | D18: Stage | E18: StageID | F18: - | G18: 9001~ | H18: 7 | I18: Y | J18: Y

Sheet UnitStat
A1: 규칙 | B1: 한 행 = 유닛 하나(플레이어·몬스터·보스 공통 스탯). 비율은 만분율(10000=100%), MoveSpeed는 타일×100/초(600=초당 6타일). 몬스터 HP·ATK·DEF·Dodge·Poise는 StatCurve 등급(Tier) 값. 16행부터의 계산 예시는 내보내지 않음.
A2: 기능 | B2: 체력·공격·방어·회피 확률·치명타·체세·이동 속도.
A3: 역할 | B3: Player·Monster·Boss·Attack이 이 ID(UnitID·OwnerID)로 가리킨다. 전투 계산과 Balance 탭이 읽는다.
A4: 의도 | B4: 유닛 공통 스탯을 한 곳에서 고치기 위해. 회피 확률(Dodge)은 구르기와 별개로 모든 유닛이 가짐.
A5: 비고 | B5: Name, Note
A6: ID | B6: Name | C6: TextID | D6: Type | E6: Tier | F6: HP | G6: ATK | H6: DEF | I6: Dodge | J6: Crit | K6: CritMult | L6: Poise | M6: MoveSpeed | N6: Active | O6: Note
A7: 1001 | B7: 막손 | C7: 30001 | D7: Player | F7: 100 | G7: 10 | H7: 0 | I7: 500 | J7: 1000 | K7: 15000 | L7: 0 | M7: 600 | N7: Y | O7: 주인공. 성장 없음(10/28)
A8: 1002 | B8: 허수귀 | C8: 30002 | D8: Monster | E8: 1 | F8: =VLOOKUP($E8,StatCurve!$A$10:$F$14,2,FALSE) -> 35 | G8: =VLOOKUP($E8,StatCurve!$A$10:$F$14,3,FALSE) -> 20 | H8: =VLOOKUP($E8,StatCurve!$A$10:$F$14,4,FALSE) -> 0 | I8: =VLOOKUP($E8,StatCurve!$A$10:$F$14,5,FALSE) -> 300 | J8: 0 | K8: 15000 | L8: =VLOOKUP($E8,StatCurve!$A$10:$F$14,6,FALSE) -> 40 | M8: 300 | N8: Y | O8: 잡몹
A9: 1003 | B9: 지게귀 | C9: 30003 | D9: Monster | E9: 2 | F9: =VLOOKUP($E9,StatCurve!$A$10:$F$14,2,FALSE) -> 50 | G9: =VLOOKUP($E9,StatCurve!$A$10:$F$14,3,FALSE) -> 26 | H9: =VLOOKUP($E9,StatCurve!$A$10:$F$14,4,FALSE) -> 500 | I9: =VLOOKUP($E9,StatCurve!$A$10:$F$14,5,FALSE) -> 400 | J9: 0 | K9: 15000 | L9: =VLOOKUP($E9,StatCurve!$A$10:$F$14,6,FALSE) -> 50 | M9: 250 | N9: Y | O9: 잡몹
A10: 1004 | B10: 불붙은 허수귀 | C10: 30004 | D10: Monster | E10: 3 | F10: =VLOOKUP($E10,StatCurve!$A$10:$F$14,2,FALSE) -> 65 | G10: =VLOOKUP($E10,StatCurve!$A$10:$F$14,3,FALSE) -> 32 | H10: =VLOOKUP($E10,StatCurve!$A$10:$F$14,4,FALSE) -> 1000 | I10: =VLOOKUP($E10,StatCurve!$A$10:$F$14,5,FALSE) -> 500 | J10: 0 | K10: 15000 | L10: =VLOOKUP($E10,StatCurve!$A$10:$F$14,6,FALSE) -> 60 | M10: 300 | N10: Y | O10: 변종, 지스타 포함 여부 미정
A11: 1005 | B11: 짐 던지는 지게귀 | C11: 30005 | D11: Monster | E11: 3 | F11: =VLOOKUP($E11,StatCurve!$A$10:$F$14,2,FALSE) -> 65 | G11: =VLOOKUP($E11,StatCurve!$A$10:$F$14,3,FALSE) -> 32 | H11: =VLOOKUP($E11,StatCurve!$A$10:$F$14,4,FALSE) -> 1000 | I11: =VLOOKUP($E11,StatCurve!$A$10:$F$14,5,FALSE) -> 500 | J11: 0 | K11: 15000 | L11: =VLOOKUP($E11,StatCurve!$A$10:$F$14,6,FALSE) -> 60 | M11: 250 | N11: Y | O11: 변종, 지스타 포함 여부 미정
A12: 1006 | B12: 쇄문아비 | C12: 30006 | D12: Boss | F12: 420 | G12: 28 | H12: 1000 | I12: 300 | J12: 500 | K12: 15000 | L12: 120 | M12: 200 | N12: Y | O12: 보스. 곡선 밖 개별 값
A16: 계산 예시 (전투 기획서 C05 공식, 위 표 값으로 자동 계산, 내보내지 않음)
A17: 공격 | B17: 공격자 ATK | C17: 배율(Attack) | D17: 치명 배율 | E17: 대상 DEF | F17: 데미지 | G17: 대상 HP | H17: 처치까지 타수 | I17: 설명
A18: 막손 1타 → 지게귀 | B18: =G7 -> 10 | C18: 10000 | D18: 10000 | E18: =H9 -> 500 | F18: =MAX(1,INT(B18*C18*D18*(10000-E18)/10^12)) -> 9 | G18: =F9 -> 50 | H18: =ROUNDUP(G18/F18,0) -> 6 | I18: 체세 해체 없이 평타만 쓸 때
A19: 막손 3타 치명타 → 쇄문아비 | B19: =G7 -> 10 | C19: 18000 | D19: =K7 -> 15000 | E19: =H12 -> 1000 | F19: =MAX(1,INT(B19*C19*D19*(10000-E19)/10^12)) -> 24 | G19: =F12 -> 420 | H19: =ROUNDUP(G19/F19,0) -> 18 | I19: 보스는 해체(최대 HP 18%)로 줄임
A20: 지게귀 돌진 → 막손 | B20: =G9 -> 26 | C20: 12000 | D20: 10000 | E20: =H7 -> 0 | F20: =MAX(1,INT(B20*C20*D20*(10000-E20)/10^12)) -> 31 | G20: =F7 -> 100 | H20: =ROUNDUP(G20/F20,0) -> 4 | I20: 막손이 버티는 횟수

Sheet Player
A1: 규칙 | B1: 한 행 = 플레이어 조작 프로필 하나. Regen은 초당, 시간은 ms, 거리는 타일×100.
A2: 기능 | B2: 스태미나·구르기·점프·피격 경직·약초·매달리기·착지·선입력.
A3: 역할 | B3: 플레이어 컨트롤러가 읽는다. UnitID는 UnitStat, StartWeapon은 Weapon ID.
A4: 의도 | B4: 조작 감각을 프로필만 바꿔 비교하기 위해. 인벤토리는 지스타 제외(완성판), 약초 개수만 HUD 표시.
A5: 비고 | B5: Name, Note
A6: ID | B6: Name | C6: UnitID | D6: StaminaMax | E6: StaminaRegen | F6: StaminaRegenDelay | G6: RollDistance | H6: RollTime | I6: RollIFrame | J6: RollStamina | K6: JumpHeight | L6: HitStunTime | M6: HitIFrame | N6: HerbHeal | O6: HerbCount | P6: HerbUseTime | Q6: HangAuto | R6: StartWeapon | S6: CritHitStunTime | T6: LandFallHeight | U6: LandTime | V6: InputBuffer | W6: Active | X6: Note
A7: 2001 | B7: 막손 기본 | C7: 1001 | D7: 100 | E7: 45 | F7: 500 | G7: 300 | H7: 500 | I7: 300 | J7: 20 | K7: 300 | L7: 300 | M7: 600 | N7: 40 | O7: 3 | P7: 800 | Q7: Y | R7: 6001 | S7: 500 | T7: 500 | U7: 200 | V7: 150 | W7: Y | X7: CritHitStunTime=치명타 피격 경직, LandFallHeight=착지 모션이 나오는 낙하 높이(5타일), InputBuffer=선입력 버퍼

Sheet Monster
A1: 규칙 | B1: 한 행 = 잡몹 하나의 AI·체세 설정. 스탯은 UnitID로 UnitStat에서 가져옴. AttackIDs는 Attack ID를 | 로 구분.
A2: 기능 | B2: AI 종류·시야·공격 거리·대기·공격 목록·체세 회복·해체 방식·슈퍼아머.
A3: 역할 | B3: 몬스터 AI와 스폰 JSON(code = 이 ID)이 읽는다.
A4: 의도 | B4: 잡몹 행동을 코드 수정 없이 바꾸기 위해.
A5: 비고 | B5: Name, Note
A6: ID | B6: Name | C6: UnitID | D6: AIType | E6: SightRange | F6: AttackRange | G6: IdleMin | H6: IdleMax | I6: AttackIDs | J6: PoiseRegenDelay | K6: PoiseRegen | L6: ExposeTime | M6: ExecuteType | N6: SuperArmor | O6: Active | P6: Note
A7: 3001 | B7: 허수귀 | C7: 1002 | D7: MELEE | E7: 800 | F7: 150 | G7: 1000 | H7: 1500 | I7: 5007|5008 | J7: 2000 | K7: 10 | L7: 1500 | M7: KILL | N7: N | O7: Y | P7: 짚 팔로 잡기
A8: 3002 | B8: 지게귀 | C8: 1003 | D8: CHARGER | E8: 800 | F8: 600 | G8: 1000 | H8: 1500 | I8: 5009|5010 | J8: 2000 | K8: 10 | L8: 1500 | M8: KILL | N8: Y | O8: Y | P8: 돌진 중 슈퍼아머
A9: 3003 | B9: 불붙은 허수귀 | C9: 1004 | D9: MELEE | E9: 800 | F9: 150 | G9: 1000 | H9: 1500 | I9: 5007|5008|5011 | J9: 2000 | K9: 10 | L9: 1500 | M9: KILL | N9: N | O9: Y | P9: 변종: 죽을 때 불 남김, 해체하면 안 남김
A10: 3004 | B10: 짐 던지는 지게귀 | C10: 1005 | D10: CHARGER | E10: 800 | F10: 600 | G10: 1000 | H10: 1500 | I10: 5009|5010|5012 | J10: 2000 | K10: 10 | L10: 1500 | M10: KILL | N10: Y | O10: Y | P10: 변종

Sheet Boss
A1: 규칙 | B1: 한 행 = 보스 페이즈 하나. 같은 보스는 UnitID가 같고 Phase로 나눔. HPThreshold·ExecuteDamage는 최대 HP 대비 만분율. AttackIDs는 | 구분.
A2: 기능 | B2: 페이즈별 공격 목록·대기·체세 회복·해체 피해.
A3: 역할 | B3: 보스 AI가 읽는다. 스탯은 UnitID로 UnitStat에서 가져옴.
A4: 의도 | B4: 페이즈를 행 추가만으로 늘리기 위해.
A5: 비고 | B5: Name, Note
A6: ID | B6: Name | C6: UnitID | D6: Phase | E6: HPThreshold | F6: AttackIDs | G6: IdleTime | H6: PoiseRegenDelay | I6: PoiseRegen | J6: ExposeTime | K6: ExecuteDamage | L6: Active | M6: Note
A7: 4001 | B7: 쇄문아비 1페이즈 | C7: 1006 | D7: 1 | E7: 10000 | F7: 5013|5014|5015 | G7: 1500 | H7: 2000 | I7: 15 | J7: 2000 | K7: 1800 | L7: Y | M7: HP 100~50%. ExecuteDamage 1800 = 최대 HP 18%
A8: 4002 | B8: 쇄문아비 2페이즈 | C8: 1006 | D8: 2 | E8: 5000 | F8: 5013|5014|5015|5016 | G8: 1000 | H8: 2000 | I8: 15 | J8: 2000 | K8: 1800 | L8: Y | M8: HP 50% 이하: 문 돌진 추가, 대기 짧아짐

Sheet Attack
A1: 규칙 | B1: 한 행 = 공격 하나. DamageMult는 만분율, 시간(Startup·ActiveTime·Recovery·ComboWindow·HitStop)은 ms. Dodgeable Y = 회피 확률 굴림, N = 반드시 들어감. 데미지 = max(1, floor(ATK × DamageMult/10000 × CritMult/10000 × (10000−DEF)/10000)), 순서: 무적 → 회피 확률 → 치명타 → 방어.
A2: 기능 | B2: 공격 배율·체세 피해·판정 타이밍·스태미나·회피 가능 여부.
A3: 역할 | B3: Weapon·Skill·Monster·Boss가 이 ID로 가리킨다. OwnerID는 UnitStat, StateID는 State ID.
A4: 의도 | B4: 공격 하나를 행 단위로 조정하기 위해. 몬스터 공격은 이름을 화면에 띄우지 않아 TextID가 비어 있음.
A5: 비고 | B5: Name, Note
A6: ID | B6: Name | C6: OwnerID | D6: TextID | E6: StateID | F6: DamageMult | G6: PoiseDamage | H6: Startup | I6: ActiveTime | J6: Recovery | K6: ComboWindow | L6: Stamina | M6: Dodgeable | N6: HitStop | O6: Active | P6: Note
A7: 5001 | B7: 발골칼 1타 | C7: 1001 | D7: 30015 | E7: 10004 | F7: 10000 | G7: 10 | H7: 120 | I7: 80 | J7: 250 | K7: 200 | L7: 12 | M7: Y | N7: 50 | O7: Y
A8: 5002 | B8: 발골칼 2타 | C8: 1001 | D8: 30016 | E8: 10005 | F8: 10000 | G8: 10 | H8: 120 | I8: 80 | J8: 250 | K8: 200 | L8: 12 | M8: Y | N8: 50 | O8: Y
A9: 5003 | B9: 발골칼 3타 | C9: 1001 | D9: 30017 | E9: 10006 | F9: 18000 | G9: 20 | H9: 200 | I9: 100 | J9: 400 | K9: 0 | L9: 12 | M9: Y | N9: 50 | O9: Y | P9: 콤보 끝
A10: 5004 | B10: 공중 1타 | C10: 1001 | D10: 30018 | E10: 10004 | F10: 8000 | G10: 10 | H10: 100 | I10: 80 | J10: 200 | K10: 0 | L10: 12 | M10: Y | N10: 50 | O10: Y
A11: 5005 | B11: 해체 | C11: 1001 | D11: 30019 | E11: 10015 | F11: 0 | G11: 0 | H11: 0 | I11: 0 | J11: 0 | K11: 0 | L11: 0 | M11: N | N11: 150 | O11: Y | P11: 잡몹 즉사, 보스는 Boss.ExecuteDamage. 회피 불가
A12: 5006 | B12: 결박 가르기 | C12: 1001 | D12: 30020 | E12: 10009 | F12: 15000 | G12: 30 | H12: 150 | I12: 120 | J12: 350 | K12: 0 | L12: 0 | M12: N | N12: 50 | O12: Y | P12: 회피 불가, 결박 끊기
A13: 5007 | B13: 허수귀 팔 휘두르기 | C13: 1002 | E13: 10004 | F13: 10000 | G13: 0 | H13: 500 | I13: 100 | J13: 400 | K13: 0 | L13: 0 | M13: Y | N13: 50 | O13: Y
A14: 5008 | B14: 허수귀 짚 팔 잡기 | C14: 1002 | E14: 10009 | F14: 5000 | G14: 0 | H14: 500 | I14: 150 | J14: 600 | K14: 0 | L14: 0 | M14: Y | N14: 50 | O14: Y | P14: 구속 1000ms, 공격 연타로 풀기
A15: 5009 | B15: 지게귀 지게 내리찍기 | C15: 1003 | E15: 10004 | F15: 10000 | G15: 0 | H15: 600 | I15: 120 | J15: 500 | K15: 0 | L15: 0 | M15: Y | N15: 50 | O15: Y
A16: 5010 | B16: 지게귀 돌진 | C16: 1003 | E16: 10009 | F16: 12000 | G16: 0 | H16: 700 | I16: 400 | J16: 800 | K16: 0 | L16: 0 | M16: Y | N16: 50 | O16: Y | P16: 슈퍼아머, 벽 충돌 시 800ms 허점
A17: 5011 | B17: 불붙은 허수귀 바닥 불 | C17: 1004 | E17: 10016 | F17: 0 | G17: 0 | H17: 0 | I17: 3000 | J17: 0 | K17: 0 | L17: 0 | M17: Y | N17: 0 | O17: Y | P17: 초당 고정 5 피해, 3000ms
A18: 5012 | B18: 짐 투척 | C18: 1005 | E18: 10005 | F18: 9000 | G18: 0 | H18: 700 | I18: 100 | J18: 500 | K18: 0 | L18: 0 | M18: Y | N18: 50 | O18: Y | P18: 포물선
A19: 5013 | B19: 쇄문아비 문짝 내리찍기 | C19: 1006 | E19: 10004 | F19: 12000 | G19: 0 | H19: 700 | I19: 150 | J19: 600 | K19: 0 | L19: 0 | M19: Y | N19: 80 | O19: Y
A20: 5014 | B20: 쇄문아비 빗장 휘두르기 | C20: 1006 | E20: 10005 | F20: 10000 | G20: 0 | H20: 500 | I20: 100 | J20: 500 | K20: 0 | L20: 0 | M20: Y | N20: 80 | O20: Y | P20: 2타(어택 2-1)
A21: 5015 | B21: 쇄문아비 사슬 당기기 | C21: 1006 | E21: 10006 | F21: 8000 | G21: 0 | H21: 900 | I21: 200 | J21: 700 | K21: 0 | L21: 0 | M21: Y | N21: 80 | O21: Y | P21: 구속, 결박 가르기로 끊기
A22: 5016 | B22: 쇄문아비 문 돌진 | C22: 1006 | E22: 10009 | F22: 15000 | G22: 0 | H22: 1000 | I22: 600 | J22: 900 | K22: 0 | L22: 0 | M22: Y | N22: 100 | O22: Y | P22: HP 50% 이하, 벽 충돌 시 보스 체세 -30

Sheet Weapon
A1: 규칙 | B1: 한 행 = 무기 하나. AttackIDs는 Attack ID를 | 로 구분, SkillID는 Skill ID.
A2: 기능 | B2: 무기별 공격 목록·스킬·획득 방식.
A3: 역할 | B3: Player.StartWeapon과 무기 획득 처리가 읽는다.
A4: 의도 | B4: 무기를 행 추가로 늘리기 위해(완성판 3종). 무기 획득 = 스킬 해금(10/28).
A5: 비고 | B5: Name, Note
A6: ID | B6: Name | C6: TextID | D6: InGstar | E6: AttackIDs | F6: SkillID | G6: Acquire | H6: AcquireAnim | I6: Active | J6: Note
A7: 6001 | B7: 발골칼 | C7: 30007 | D7: Y | E7: 5001|5002|5003|5004 | F7: 7001 | G7: START | H7: ANIM_ACQ_6001 | I7: Y | J7: 시작 무기. 결박 가르기는 장부방 해금(예외, 10/28)
A8: 6002 | B8: 버선칼 | C8: 30008 | D8: N | G8: STORY | H8: ANIM_ACQ_6002 | I8: Y | J8: 완성판, 획득 시 스킬 해금
A9: 6003 | B9: 쇠메 | C9: 30009 | D9: N | G9: STORY | H9: ANIM_ACQ_6003 | I9: Y | J9: 완성판, 획득 시 스킬 해금

Sheet Skill
A1: 규칙 | B1: 한 행 = 스킬 하나. MP 없음, Cooldown(ms)만. WeaponID는 Weapon ID, AttackID는 Attack ID.
A2: 기능 | B2: 스킬 공격·쿨타임·해금 방식·효과.
A3: 역할 | B3: 스킬 입력과 해금 처리가 읽는다.
A4: 의도 | B4: 무기마다 스킬을 붙이기 위해.
A5: 비고 | B5: Name, Note
A6: ID | B6: Name | C6: TextID | D6: WeaponID | E6: AttackID | F6: Cooldown | G6: UnlockType | H6: Effect | I6: Active | J6: Note
A7: 7001 | B7: 결박 가르기 | C7: 30010 | D7: 6001 | E7: 5006 | F7: 8000 | G7: ROOM_LEDGER | H7: CUT_BIND | I7: Y | J7: 장부방에서 해금, 결박 문·사슬 끊기

Sheet StatCurve
A1: Stat | B1: Base | C1: Delta | D1: 설명
A2: HP | B2: 20 | C2: 15 | D2: 체력
A3: ATK | B3: 14 | C3: 6 | D3: 공격력
A4: DEF | B4: -500 | C4: 500 | D4: 피해 감소율(만분율), 최대 5000
A5: Dodge | B5: 200 | C5: 100 | D5: 회피 확률(만분율), 구르기와 별개
A6: Poise | B6: 30 | C6: 10 | D6: 체세 최대치
A8: 등급별 값 = Base + Delta × Tier (Base·Delta만 고치면 아래 표와 그래프가 같이 바뀜)
A9: Tier | B9: HP | C9: ATK | D9: DEF | E9: Dodge | F9: Poise | G9: 해당 몬스터
A10: 1 | B10: =$B$2+$C$2*$A10 -> 35 | C10: =$B$3+$C$3*$A10 -> 20 | D10: =$B$4+$C$4*$A10 -> 0 | E10: =$B$5+$C$5*$A10 -> 300 | F10: =$B$6+$C$6*$A10 -> 40 | G10: 허수귀
A11: 2 | B11: =$B$2+$C$2*$A11 -> 50 | C11: =$B$3+$C$3*$A11 -> 26 | D11: =$B$4+$C$4*$A11 -> 500 | E11: =$B$5+$C$5*$A11 -> 400 | F11: =$B$6+$C$6*$A11 -> 50 | G11: 지게귀
A12: 3 | B12: =$B$2+$C$2*$A12 -> 65 | C12: =$B$3+$C$3*$A12 -> 32 | D12: =$B$4+$C$4*$A12 -> 1000 | E12: =$B$5+$C$5*$A12 -> 500 | F12: =$B$6+$C$6*$A12 -> 60 | G12: 변종 (불붙은 허수귀, 짐 던지는 지게귀)
A13: 4 | B13: =$B$2+$C$2*$A13 -> 80 | C13: =$B$3+$C$3*$A13 -> 38 | D13: =$B$4+$C$4*$A13 -> 1500 | E13: =$B$5+$C$5*$A13 -> 600 | F13: =$B$6+$C$6*$A13 -> 70 | G13: 완성판 예비
A14: 5 | B14: =$B$2+$C$2*$A14 -> 95 | C14: =$B$3+$C$3*$A14 -> 44 | D14: =$B$4+$C$4*$A14 -> 2000 | E14: =$B$5+$C$5*$A14 -> 700 | F14: =$B$6+$C$6*$A14 -> 80 | G14: 완성판 예비

Sheet Balance
A1: 밸런스 계산기: 공격력·치명타와 회피 확률
A2: 노란 칸만 입력합니다. 가정값을 비워 두면 UnitStat·Attack·Boss 시트 값을 그대로 씁니다. 나머지 칸은 모두 수식입니다.
A3: 기대 데미지 = (1 − 대상 회피율) × [(1 − 치명타율) × 평타 데미지 + 치명타율 × 치명 데미지]. 데미지 공식은 전투 기획서 C05와 같습니다. 계산용 탭이라 CSV로 내보내지 않습니다.
A5: 1. 막손 값
A6: 항목 | B6: 키(ID) | C6: 시트 값 | D6: 가정값(입력) | E6: 계산에 쓰는 값
A7: 공격력 ATK | B7: 1001 | C7: {=INDEX(UnitStat!$G:$G,MATCH($B7,UnitStat!$A:$A,0))} -> 10 | E7: =IF(D7="",C7,D7) -> 10
A8: 치명타율 Crit | B8: 1001 | C8: {=INDEX(UnitStat!$J:$J,MATCH($B8,UnitStat!$A:$A,0))} -> 1000 | E8: =IF(D8="",C8,D8) -> 1000
A9: 치명 배율 CritMult | B9: 1001 | C9: {=INDEX(UnitStat!$K:$K,MATCH($B9,UnitStat!$A:$A,0))} -> 15000 | E9: =IF(D9="",C9,D9) -> 15000
A10: HP | B10: 1001 | C10: {=INDEX(UnitStat!$F:$F,MATCH($B10,UnitStat!$A:$A,0))} -> 100 | E10: =IF(D10="",C10,D10) -> 100
A11: 방어 DEF | B11: 1001 | C11: {=INDEX(UnitStat!$H:$H,MATCH($B11,UnitStat!$A:$A,0))} -> 0 | E11: =IF(D11="",C11,D11) -> 0
A12: 회피율 Dodge | B12: 1001 | C12: {=INDEX(UnitStat!$I:$I,MATCH($B12,UnitStat!$A:$A,0))} -> 500 | E12: =IF(D12="",C12,D12) -> 500
A13: 1타 배율 | B13: 5001 | C13: {=INDEX(Attack!$F:$F,MATCH($B13,Attack!$A:$A,0))} -> 10000 | E13: =IF(D13="",C13,D13) -> 10000
A14: 2타 배율 | B14: 5002 | C14: {=INDEX(Attack!$F:$F,MATCH($B14,Attack!$A:$A,0))} -> 10000 | E14: =IF(D14="",C14,D14) -> 10000
A15: 3타 배율 | B15: 5003 | C15: {=INDEX(Attack!$F:$F,MATCH($B15,Attack!$A:$A,0))} -> 18000 | E15: =IF(D15="",C15,D15) -> 18000
A16: 1타 체세 피해 | B16: 5001 | C16: {=INDEX(Attack!$G:$G,MATCH($B16,Attack!$A:$A,0))} -> 10 | E16: =IF(D16="",C16,D16) -> 10
A17: 2타 체세 피해 | B17: 5002 | C17: {=INDEX(Attack!$G:$G,MATCH($B17,Attack!$A:$A,0))} -> 10 | E17: =IF(D17="",C17,D17) -> 10
A18: 3타 체세 피해 | B18: 5003 | C18: {=INDEX(Attack!$G:$G,MATCH($B18,Attack!$A:$A,0))} -> 20 | E18: =IF(D18="",C18,D18) -> 20
A19: 콤보 1회 시간(ms) | B19: 1~3타 선딜+판정+후딜 | C19: {=SUM(INDEX(Attack!$H:$J,MATCH($B13,Attack!$A:$A,0),0))+SUM(INDEX(Attack!$H:$J,MATCH($B14,Attack!$A:$A,0),0))+SUM(INDEX(Attack!$H:$J,MATCH($B15,Attack!$A:$A,0),0))} -> 1600 | E19: =IF(D19="",C19,D19) -> 1600
A21: 2. 막손 → 적 (회피·치명타 반영 기대값)
A22: 대상 UnitID | B22: 이름 | C22: HP | D22: DEF | E22: 회피율(시트) | F22: 회피율 가정(입력) | G22: 회피율 사용 | H22: 체세 | I22: 1타 평타 | J22: 1타 치명 | K22: 2타 평타 | L22: 2타 치명 | M22: 3타 평타 | N22: 3타 치명 | O22: 1타 기대 데미지 | P22: 콤보 기대 데미지 | Q22: 콤보 기대 체세 피해 | R22: 평타만으로 처치 콤보 | S22: 체세 붕괴까지 콤보 | T22: 해체 1회 피해 | U22: 처치까지 콤보(해체 포함) | V22: 해체 횟수 | W22: 처치 시간(초) | X22: 1타만 처치 타수(회피·치명 없음) | Y22: 1타만 처치 기대 타수 | Z22: 처치 방식
A23: 1002 | B23: {=INDEX(UnitStat!$B:$B,MATCH($A23,UnitStat!$A:$A,0))} -> 허수귀 | C23: {=INDEX(UnitStat!$F:$F,MATCH($A23,UnitStat!$A:$A,0))} -> 35 | D23: {=INDEX(UnitStat!$H:$H,MATCH($A23,UnitStat!$A:$A,0))} -> 0 | E23: {=INDEX(UnitStat!$I:$I,MATCH($A23,UnitStat!$A:$A,0))} -> 300 | G23: =IF($F23="",$E23,$F23) -> 300 | H23: {=INDEX(UnitStat!$L:$L,MATCH($A23,UnitStat!$A:$A,0))} -> 40 | I23: =MAX(1,INT($E$7*$E$13*10000*(10000-$D23)/10^12+0.000000001)) -> 10 | J23: =MAX(1,INT($E$7*$E$13*$E$9*(10000-$D23)/10^12+0.000000001)) -> 15 | K23: =MAX(1,INT($E$7*$E$14*10000*(10000-$D23)/10^12+0.000000001)) -> 10 | L23: =MAX(1,INT($E$7*$E$14*$E$9*(10000-$D23)/10^12+0.000000001)) -> 15 | M23: =MAX(1,INT($E$7*$E$15*10000*(10000-$D23)/10^12+0.000000001)) -> 18 | N23: =MAX(1,INT($E$7*$E$15*$E$9*(10000-$D23)/10^12+0.000000001)) -> 27 | O23: =(1-$G23/10000)*((1-$E$8/10000)*$I23+$E$8/10000*$J23) -> 10.185 | P23: =(1-$G23/10000)*((1-$E$8/10000)*($I23+$K23+$M23)+$E$8/10000*($J23+$L23+$N23)) -> 38.703 | Q23: =(1-$G23/10000)*($E$16+$E$17+$E$18) -> 38.8 | R23: =$C23/$P23 -> 0.90432266 | S23: =$H23/$Q23 -> 1.0309278 | T23: {=IF(INDEX(UnitStat!$D:$D,MATCH($A23,UnitStat!$A:$A,0))="Boss",INT($C23*INDEX(Boss!$K:$K,MATCH($A23,Boss!$C:$C,0))/10000),"즉사")} -> 즉사 | U23: =IF(ISNUMBER($T23),$C23/($S23*$P23+$T23)*$S23,MIN($R23,$S23)) -> 0.90432266 | V23: =IF(ISNUMBER($T23),$C23/($S23*$P23+$T23),IF($S23<=$R23,1,0)) -> 0 | W23: =$U23*$E$19/1000 -> 1.4469163 | X23: =ROUNDUP($C23/$I23,0) -> 4 | Y23: =$C23/$O23 -> 3.4364261 | Z23: =IF(ISNUMBER($T23),"체세 붕괴 → 해체 반복",IF($S23<=$R23,"체세 먼저 무너짐 → 해체","HP 먼저 바닥 → 평타로 처치")) -> HP 먼저 바닥 → 평타로 처치
A24: 1003 | B24: {=INDEX(UnitStat!$B:$B,MATCH($A24,UnitStat!$A:$A,0))} -> 지게귀 | C24: {=INDEX(UnitStat!$F:$F,MATCH($A24,UnitStat!$A:$A,0))} -> 50 | D24: {=INDEX(UnitStat!$H:$H,MATCH($A24,UnitStat!$A:$A,0))} -> 500 | E24: {=INDEX(UnitStat!$I:$I,MATCH($A24,UnitStat!$A:$A,0))} -> 400 | G24: =IF($F24="",$E24,$F24) -> 400 | H24: {=INDEX(UnitStat!$L:$L,MATCH($A24,UnitStat!$A:$A,0))} -> 50 | I24: =MAX(1,INT($E$7*$E$13*10000*(10000-$D24)/10^12+0.000000001)) -> 9 | J24: =MAX(1,INT($E$7*$E$13*$E$9*(10000-$D24)/10^12+0.000000001)) -> 14 | K24: =MAX(1,INT($E$7*$E$14*10000*(10000-$D24)/10^12+0.000000001)) -> 9 | L24: =MAX(1,INT($E$7*$E$14*$E$9*(10000-$D24)/10^12+0.000000001)) -> 14 | M24: =MAX(1,INT($E$7*$E$15*10000*(10000-$D24)/10^12+0.000000001)) -> 17 | N24: =MAX(1,INT($E$7*$E$15*$E$9*(10000-$D24)/10^12+0.000000001)) -> 25 | O24: =(1-$G24/10000)*((1-$E$8/10000)*$I24+$E$8/10000*$J24) -> 9.12 | P24: =(1-$G24/10000)*((1-$E$8/10000)*($I24+$K24+$M24)+$E$8/10000*($J24+$L24+$N24)) -> 35.328 | Q24: =(1-$G24/10000)*($E$16+$E$17+$E$18) -> 38.4 | R24: =$C24/$P24 -> 1.415308 | S24: =$H24/$Q24 -> 1.3020833 | T24: {=IF(INDEX(UnitStat!$D:$D,MATCH($A24,UnitStat!$A:$A,0))="Boss",INT($C24*INDEX(Boss!$K:$K,MATCH($A24,Boss!$C:$C,0))/10000),"즉사")} -> 즉사 | U24: =IF(ISNUMBER($T24),$C24/($S24*$P24+$T24)*$S24,MIN($R24,$S24)) -> 1.3020833 | V24: =IF(ISNUMBER($T24),$C24/($S24*$P24+$T24),IF($S24<=$R24,1,0)) -> 1 | W24: =$U24*$E$19/1000 -> 2.0833333 | X24: =ROUNDUP($C24/$I24,0) -> 6 | Y24: =$C24/$O24 -> 5.4824561 | Z24: =IF(ISNUMBER($T24),"체세 붕괴 → 해체 반복",IF($S24<=$R24,"체세 먼저 무너짐 → 해체","HP 먼저 바닥 → 평타로 처치")) -> 체세 먼저 무너짐 → 해체
A25: 1004 | B25: {=INDEX(UnitStat!$B:$B,MATCH($A25,UnitStat!$A:$A,0))} -> 불붙은 허수귀 | C25: {=INDEX(UnitStat!$F:$F,MATCH($A25,UnitStat!$A:$A,0))} -> 65 | D25: {=INDEX(UnitStat!$H:$H,MATCH($A25,UnitStat!$A:$A,0))} -> 1000 | E25: {=INDEX(UnitStat!$I:$I,MATCH($A25,UnitStat!$A:$A,0))} -> 500 | G25: =IF($F25="",$E25,$F25) -> 500 | H25: {=INDEX(UnitStat!$L:$L,MATCH($A25,UnitStat!$A:$A,0))} -> 60 | I25: =MAX(1,INT($E$7*$E$13*10000*(10000-$D25)/10^12+0.000000001)) -> 9 | J25: =MAX(1,INT($E$7*$E$13*$E$9*(10000-$D25)/10^12+0.000000001)) -> 13 | K25: =MAX(1,INT($E$7*$E$14*10000*(10000-$D25)/10^12+0.000000001)) -> 9 | L25: =MAX(1,INT($E$7*$E$14*$E$9*(10000-$D25)/10^12+0.000000001)) -> 13 | M25: =MAX(1,INT($E$7*$E$15*10000*(10000-$D25)/10^12+0.000000001)) -> 16 | N25: =MAX(1,INT($E$7*$E$15*$E$9*(10000-$D25)/10^12+0.000000001)) -> 24 | O25: =(1-$G25/10000)*((1-$E$8/10000)*$I25+$E$8/10000*$J25) -> 8.93 | P25: =(1-$G25/10000)*((1-$E$8/10000)*($I25+$K25+$M25)+$E$8/10000*($J25+$L25+$N25)) -> 33.82 | Q25: =(1-$G25/10000)*($E$16+$E$17+$E$18) -> 38 | R25: =$C25/$P25 -> 1.9219397 | S25: =$H25/$Q25 -> 1.5789474 | T25: {=IF(INDEX(UnitStat!$D:$D,MATCH($A25,UnitStat!$A:$A,0))="Boss",INT($C25*INDEX(Boss!$K:$K,MATCH($A25,Boss!$C:$C,0))/10000),"즉사")} -> 즉사 | U25: =IF(ISNUMBER($T25),$C25/($S25*$P25+$T25)*$S25,MIN($R25,$S25)) -> 1.5789474 | V25: =IF(ISNUMBER($T25),$C25/($S25*$P25+$T25),IF($S25<=$R25,1,0)) -> 1 | W25: =$U25*$E$19/1000 -> 2.5263158 | X25: =ROUNDUP($C25/$I25,0) -> 8 | Y25: =$C25/$O25 -> 7.2788354 | Z25: =IF(ISNUMBER($T25),"체세 붕괴 → 해체 반복",IF($S25<=$R25,"체세 먼저 무너짐 → 해체","HP 먼저 바닥 → 평타로 처치")) -> 체세 먼저 무너짐 → 해체
A26: 1005 | B26: {=INDEX(UnitStat!$B:$B,MATCH($A26,UnitStat!$A:$A,0))} -> 짐 던지는 지게귀 | C26: {=INDEX(UnitStat!$F:$F,MATCH($A26,UnitStat!$A:$A,0))} -> 65 | D26: {=INDEX(UnitStat!$H:$H,MATCH($A26,UnitStat!$A:$A,0))} -> 1000 | E26: {=INDEX(UnitStat!$I:$I,MATCH($A26,UnitStat!$A:$A,0))} -> 500 | G26: =IF($F26="",$E26,$F26) -> 500 | H26: {=INDEX(UnitStat!$L:$L,MATCH($A26,UnitStat!$A:$A,0))} -> 60 | I26: =MAX(1,INT($E$7*$E$13*10000*(10000-$D26)/10^12+0.000000001)) -> 9 | J26: =MAX(1,INT($E$7*$E$13*$E$9*(10000-$D26)/10^12+0.000000001)) -> 13 | K26: =MAX(1,INT($E$7*$E$14*10000*(10000-$D26)/10^12+0.000000001)) -> 9 | L26: =MAX(1,INT($E$7*$E$14*$E$9*(10000-$D26)/10^12+0.000000001)) -> 13 | M26: =MAX(1,INT($E$7*$E$15*10000*(10000-$D26)/10^12+0.000000001)) -> 16 | N26: =MAX(1,INT($E$7*$E$15*$E$9*(10000-$D26)/10^12+0.000000001)) -> 24 | O26: =(1-$G26/10000)*((1-$E$8/10000)*$I26+$E$8/10000*$J26) -> 8.93 | P26: =(1-$G26/10000)*((1-$E$8/10000)*($I26+$K26+$M26)+$E$8/10000*($J26+$L26+$N26)) -> 33.82 | Q26: =(1-$G26/10000)*($E$16+$E$17+$E$18) -> 38 | R26: =$C26/$P26 -> 1.9219397 | S26: =$H26/$Q26 -> 1.5789474 | T26: {=IF(INDEX(UnitStat!$D:$D,MATCH($A26,UnitStat!$A:$A,0))="Boss",INT($C26*INDEX(Boss!$K:$K,MATCH($A26,Boss!$C:$C,0))/10000),"즉사")} -> 즉사 | U26: =IF(ISNUMBER($T26),$C26/($S26*$P26+$T26)*$S26,MIN($R26,$S26)) -> 1.5789474 | V26: =IF(ISNUMBER($T26),$C26/($S26*$P26+$T26),IF($S26<=$R26,1,0)) -> 1 | W26: =$U26*$E$19/1000 -> 2.5263158 | X26: =ROUNDUP($C26/$I26,0) -> 8 | Y26: =$C26/$O26 -> 7.2788354 | Z26: =IF(ISNUMBER($T26),"체세 붕괴 → 해체 반복",IF($S26<=$R26,"체세 먼저 무너짐 → 해체","HP 먼저 바닥 → 평타로 처치")) -> 체세 먼저 무너짐 → 해체
A27: 1006 | B27: {=INDEX(UnitStat!$B:$B,MATCH($A27,UnitStat!$A:$A,0))} -> 쇄문아비 | C27: {=INDEX(UnitStat!$F:$F,MATCH($A27,UnitStat!$A:$A,0))} -> 420 | D27: {=INDEX(UnitStat!$H:$H,MATCH($A27,UnitStat!$A:$A,0))} -> 1000 | E27: {=INDEX(UnitStat!$I:$I,MATCH($A27,UnitStat!$A:$A,0))} -> 300 | G27: =IF($F27="",$E27,$F27) -> 300 | H27: {=INDEX(UnitStat!$L:$L,MATCH($A27,UnitStat!$A:$A,0))} -> 120 | I27: =MAX(1,INT($E$7*$E$13*10000*(10000-$D27)/10^12+0.000000001)) -> 9 | J27: =MAX(1,INT($E$7*$E$13*$E$9*(10000-$D27)/10^12+0.000000001)) -> 13 | K27: =MAX(1,INT($E$7*$E$14*10000*(10000-$D27)/10^12+0.000000001)) -> 9 | L27: =MAX(1,INT($E$7*$E$14*$E$9*(10000-$D27)/10^12+0.000000001)) -> 13 | M27: =MAX(1,INT($E$7*$E$15*10000*(10000-$D27)/10^12+0.000000001)) -> 16 | N27: =MAX(1,INT($E$7*$E$15*$E$9*(10000-$D27)/10^12+0.000000001)) -> 24 | O27: =(1-$G27/10000)*((1-$E$8/10000)*$I27+$E$8/10000*$J27) -> 9.118 | P27: =(1-$G27/10000)*((1-$E$8/10000)*($I27+$K27+$M27)+$E$8/10000*($J27+$L27+$N27)) -> 34.532 | Q27: =(1-$G27/10000)*($E$16+$E$17+$E$18) -> 38.8 | R27: =$C27/$P27 -> 12.162632 | S27: =$H27/$Q27 -> 3.0927835 | T27: {=IF(INDEX(UnitStat!$D:$D,MATCH($A27,UnitStat!$A:$A,0))="Boss",INT($C27*INDEX(Boss!$K:$K,MATCH($A27,Boss!$C:$C,0))/10000),"즉사")} -> 75 | U27: =IF(ISNUMBER($T27),$C27/($S27*$P27+$T27)*$S27,MIN($R27,$S27)) -> 7.1450444 | V27: =IF(ISNUMBER($T27),$C27/($S27*$P27+$T27),IF($S27<=$R27,1,0)) -> 2.310231 | W27: =$U27*$E$19/1000 -> 11.432071 | X27: =ROUNDUP($C27/$I27,0) -> 47 | Y27: =$C27/$O27 -> 46.062733 | Z27: =IF(ISNUMBER($T27),"체세 붕괴 → 해체 반복",IF($S27<=$R27,"체세 먼저 무너짐 → 해체","HP 먼저 바닥 → 평타로 처치")) -> 체세 붕괴 → 해체 반복
A28: 보스: 처치까지 콤보 = HP ÷ (체세 붕괴까지 콤보 × 콤보 기대 데미지 + 해체 1회 피해) × 체세 붕괴까지 콤보. 체세 회복(마지막 피격 2초 뒤)과 결박 가르기는 넣지 않은 근사치입니다. 비교 목표(C10 기준 체감): 잡몹 콤보 1~2번·3~5초, 보스 해체 3~4번.
A30: 3. 적 → 막손 (막손 회피율 반영 기대값)
A31: AttackID | B31: 공격자 | C31: 설명 | D31: 공격자 ATK | E31: 배율 | F31: 회피 가능 | G31: 공격자 치명타율 | H31: 치명 배율 | I31: 평타 데미지 | J31: 치명 데미지 | K31: 기대 데미지 | L31: 쓰러질 때까지 피격(회피·치명 없음) | M31: 쓰러질 때까지 기대 피격 | N31: 목표 최소(입력) | O31: 목표 최대(입력) | P31: 판정
A32: 5007 | B32: {=INDEX(Attack!$C:$C,MATCH($A32,Attack!$A:$A,0))} -> 1002 | C32: {=INDEX(Attack!$B:$B,MATCH($A32,Attack!$A:$A,0))} -> 허수귀 팔 휘두르기 | D32: {=INDEX(UnitStat!$G:$G,MATCH($B32,UnitStat!$A:$A,0))} -> 20 | E32: {=INDEX(Attack!$F:$F,MATCH($A32,Attack!$A:$A,0))} -> 10000 | F32: {=INDEX(Attack!$M:$M,MATCH($A32,Attack!$A:$A,0))} -> Y | G32: {=INDEX(UnitStat!$J:$J,MATCH($B32,UnitStat!$A:$A,0))} -> 0 | H32: {=INDEX(UnitStat!$K:$K,MATCH($B32,UnitStat!$A:$A,0))} -> 15000 | I32: =MAX(1,INT($D32*$E32*10000*(10000-$E$11)/10^12+0.000000001)) -> 20 | J32: =MAX(1,INT($D32*$E32*$H32*(10000-$E$11)/10^12+0.000000001)) -> 30 | K32: =(1-IF($F32="Y",$E$12,0)/10000)*((1-$G32/10000)*$I32+$G32/10000*$J32) -> 19 | L32: =ROUNDUP($E$10/$I32,0) -> 5 | M32: =$E$10/$K32 -> 5.2631579 | N32: 4 | O32: 5 | P32: =IF($N32="","구속 공격(비교 안 함)",IF(AND($L32>=$N32,$L32<=$O32),"목표 안",IF($L32<$N32,"목표보다 아픔","목표보다 약함"))) -> 목표 안
A33: 5008 | B33: {=INDEX(Attack!$C:$C,MATCH($A33,Attack!$A:$A,0))} -> 1002 | C33: {=INDEX(Attack!$B:$B,MATCH($A33,Attack!$A:$A,0))} -> 허수귀 짚 팔 잡기 | D33: {=INDEX(UnitStat!$G:$G,MATCH($B33,UnitStat!$A:$A,0))} -> 20 | E33: {=INDEX(Attack!$F:$F,MATCH($A33,Attack!$A:$A,0))} -> 5000 | F33: {=INDEX(Attack!$M:$M,MATCH($A33,Attack!$A:$A,0))} -> Y | G33: {=INDEX(UnitStat!$J:$J,MATCH($B33,UnitStat!$A:$A,0))} -> 0 | H33: {=INDEX(UnitStat!$K:$K,MATCH($B33,UnitStat!$A:$A,0))} -> 15000 | I33: =MAX(1,INT($D33*$E33*10000*(10000-$E$11)/10^12+0.000000001)) -> 10 | J33: =MAX(1,INT($D33*$E33*$H33*(10000-$E$11)/10^12+0.000000001)) -> 15 | K33: =(1-IF($F33="Y",$E$12,0)/10000)*((1-$G33/10000)*$I33+$G33/10000*$J33) -> 9.5 | L33: =ROUNDUP($E$10/$I33,0) -> 10 | M33: =$E$10/$K33 -> 10.526316 | P33: =IF($N33="","구속 공격(비교 안 함)",IF(AND($L33>=$N33,$L33<=$O33),"목표 안",IF($L33<$N33,"목표보다 아픔","목표보다 약함"))) -> 구속 공격(비교 안 함)
A34: 5009 | B34: {=INDEX(Attack!$C:$C,MATCH($A34,Attack!$A:$A,0))} -> 1003 | C34: {=INDEX(Attack!$B:$B,MATCH($A34,Attack!$A:$A,0))} -> 지게귀 지게 내리찍기 | D34: {=INDEX(UnitStat!$G:$G,MATCH($B34,UnitStat!$A:$A,0))} -> 26 | E34: {=INDEX(Attack!$F:$F,MATCH($A34,Attack!$A:$A,0))} -> 10000 | F34: {=INDEX(Attack!$M:$M,MATCH($A34,Attack!$A:$A,0))} -> Y | G34: {=INDEX(UnitStat!$J:$J,MATCH($B34,UnitStat!$A:$A,0))} -> 0 | H34: {=INDEX(UnitStat!$K:$K,MATCH($B34,UnitStat!$A:$A,0))} -> 15000 | I34: =MAX(1,INT($D34*$E34*10000*(10000-$E$11)/10^12+0.000000001)) -> 26 | J34: =MAX(1,INT($D34*$E34*$H34*(10000-$E$11)/10^12+0.000000001)) -> 39 | K34: =(1-IF($F34="Y",$E$12,0)/10000)*((1-$G34/10000)*$I34+$G34/10000*$J34) -> 24.7 | L34: =ROUNDUP($E$10/$I34,0) -> 4 | M34: =$E$10/$K34 -> 4.048583 | N34: 4 | O34: 5 | P34: =IF($N34="","구속 공격(비교 안 함)",IF(AND($L34>=$N34,$L34<=$O34),"목표 안",IF($L34<$N34,"목표보다 아픔","목표보다 약함"))) -> 목표 안
A35: 5010 | B35: {=INDEX(Attack!$C:$C,MATCH($A35,Attack!$A:$A,0))} -> 1003 | C35: {=INDEX(Attack!$B:$B,MATCH($A35,Attack!$A:$A,0))} -> 지게귀 돌진 | D35: {=INDEX(UnitStat!$G:$G,MATCH($B35,UnitStat!$A:$A,0))} -> 26 | E35: {=INDEX(Attack!$F:$F,MATCH($A35,Attack!$A:$A,0))} -> 12000 | F35: {=INDEX(Attack!$M:$M,MATCH($A35,Attack!$A:$A,0))} -> Y | G35: {=INDEX(UnitStat!$J:$J,MATCH($B35,UnitStat!$A:$A,0))} -> 0 | H35: {=INDEX(UnitStat!$K:$K,MATCH($B35,UnitStat!$A:$A,0))} -> 15000 | I35: =MAX(1,INT($D35*$E35*10000*(10000-$E$11)/10^12+0.000000001)) -> 31 | J35: =MAX(1,INT($D35*$E35*$H35*(10000-$E$11)/10^12+0.000000001)) -> 46 | K35: =(1-IF($F35="Y",$E$12,0)/10000)*((1-$G35/10000)*$I35+$G35/10000*$J35) -> 29.45 | L35: =ROUNDUP($E$10/$I35,0) -> 4 | M35: =$E$10/$K35 -> 3.3955857 | N35: 4 | O35: 5 | P35: =IF($N35="","구속 공격(비교 안 함)",IF(AND($L35>=$N35,$L35<=$O35),"목표 안",IF($L35<$N35,"목표보다 아픔","목표보다 약함"))) -> 목표 안
A36: 5012 | B36: {=INDEX(Attack!$C:$C,MATCH($A36,Attack!$A:$A,0))} -> 1005 | C36: {=INDEX(Attack!$B:$B,MATCH($A36,Attack!$A:$A,0))} -> 짐 투척 | D36: {=INDEX(UnitStat!$G:$G,MATCH($B36,UnitStat!$A:$A,0))} -> 32 | E36: {=INDEX(Attack!$F:$F,MATCH($A36,Attack!$A:$A,0))} -> 9000 | F36: {=INDEX(Attack!$M:$M,MATCH($A36,Attack!$A:$A,0))} -> Y | G36: {=INDEX(UnitStat!$J:$J,MATCH($B36,UnitStat!$A:$A,0))} -> 0 | H36: {=INDEX(UnitStat!$K:$K,MATCH($B36,UnitStat!$A:$A,0))} -> 15000 | I36: =MAX(1,INT($D36*$E36*10000*(10000-$E$11)/10^12+0.000000001)) -> 28 | J36: =MAX(1,INT($D36*$E36*$H36*(10000-$E$11)/10^12+0.000000001)) -> 43 | K36: =(1-IF($F36="Y",$E$12,0)/10000)*((1-$G36/10000)*$I36+$G36/10000*$J36) -> 26.6 | L36: =ROUNDUP($E$10/$I36,0) -> 4 | M36: =$E$10/$K36 -> 3.7593985 | N36: 4 | O36: 5 | P36: =IF($N36="","구속 공격(비교 안 함)",IF(AND($L36>=$N36,$L36<=$O36),"목표 안",IF($L36<$N36,"목표보다 아픔","목표보다 약함"))) -> 목표 안
A37: 5013 | B37: {=INDEX(Attack!$C:$C,MATCH($A37,Attack!$A:$A,0))} -> 1006 | C37: {=INDEX(Attack!$B:$B,MATCH($A37,Attack!$A:$A,0))} -> 쇄문아비 문짝 내리찍기 | D37: {=INDEX(UnitStat!$G:$G,MATCH($B37,UnitStat!$A:$A,0))} -> 28 | E37: {=INDEX(Attack!$F:$F,MATCH($A37,Attack!$A:$A,0))} -> 12000 | F37: {=INDEX(Attack!$M:$M,MATCH($A37,Attack!$A:$A,0))} -> Y | G37: {=INDEX(UnitStat!$J:$J,MATCH($B37,UnitStat!$A:$A,0))} -> 500 | H37: {=INDEX(UnitStat!$K:$K,MATCH($B37,UnitStat!$A:$A,0))} -> 15000 | I37: =MAX(1,INT($D37*$E37*10000*(10000-$E$11)/10^12+0.000000001)) -> 33 | J37: =MAX(1,INT($D37*$E37*$H37*(10000-$E$11)/10^12+0.000000001)) -> 50 | K37: =(1-IF($F37="Y",$E$12,0)/10000)*((1-$G37/10000)*$I37+$G37/10000*$J37) -> 32.1575 | L37: =ROUNDUP($E$10/$I37,0) -> 4 | M37: =$E$10/$K37 -> 3.1096945 | N37: 3 | O37: 4 | P37: =IF($N37="","구속 공격(비교 안 함)",IF(AND($L37>=$N37,$L37<=$O37),"목표 안",IF($L37<$N37,"목표보다 아픔","목표보다 약함"))) -> 목표 안
A38: 5014 | B38: {=INDEX(Attack!$C:$C,MATCH($A38,Attack!$A:$A,0))} -> 1006 | C38: {=INDEX(Attack!$B:$B,MATCH($A38,Attack!$A:$A,0))} -> 쇄문아비 빗장 휘두르기 | D38: {=INDEX(UnitStat!$G:$G,MATCH($B38,UnitStat!$A:$A,0))} -> 28 | E38: {=INDEX(Attack!$F:$F,MATCH($A38,Attack!$A:$A,0))} -> 10000 | F38: {=INDEX(Attack!$M:$M,MATCH($A38,Attack!$A:$A,0))} -> Y | G38: {=INDEX(UnitStat!$J:$J,MATCH($B38,UnitStat!$A:$A,0))} -> 500 | H38: {=INDEX(UnitStat!$K:$K,MATCH($B38,UnitStat!$A:$A,0))} -> 15000 | I38: =MAX(1,INT($D38*$E38*10000*(10000-$E$11)/10^12+0.000000001)) -> 28 | J38: =MAX(1,INT($D38*$E38*$H38*(10000-$E$11)/10^12+0.000000001)) -> 42 | K38: =(1-IF($F38="Y",$E$12,0)/10000)*((1-$G38/10000)*$I38+$G38/10000*$J38) -> 27.265 | L38: =ROUNDUP($E$10/$I38,0) -> 4 | M38: =$E$10/$K38 -> 3.6677058 | N38: 3 | O38: 4 | P38: =IF($N38="","구속 공격(비교 안 함)",IF(AND($L38>=$N38,$L38<=$O38),"목표 안",IF($L38<$N38,"목표보다 아픔","목표보다 약함"))) -> 목표 안
A39: 5015 | B39: {=INDEX(Attack!$C:$C,MATCH($A39,Attack!$A:$A,0))} -> 1006 | C39: {=INDEX(Attack!$B:$B,MATCH($A39,Attack!$A:$A,0))} -> 쇄문아비 사슬 당기기 | D39: {=INDEX(UnitStat!$G:$G,MATCH($B39,UnitStat!$A:$A,0))} -> 28 | E39: {=INDEX(Attack!$F:$F,MATCH($A39,Attack!$A:$A,0))} -> 8000 | F39: {=INDEX(Attack!$M:$M,MATCH($A39,Attack!$A:$A,0))} -> Y | G39: {=INDEX(UnitStat!$J:$J,MATCH($B39,UnitStat!$A:$A,0))} -> 500 | H39: {=INDEX(UnitStat!$K:$K,MATCH($B39,UnitStat!$A:$A,0))} -> 15000 | I39: =MAX(1,INT($D39*$E39*10000*(10000-$E$11)/10^12+0.000000001)) -> 22 | J39: =MAX(1,INT($D39*$E39*$H39*(10000-$E$11)/10^12+0.000000001)) -> 33 | K39: =(1-IF($F39="Y",$E$12,0)/10000)*((1-$G39/10000)*$I39+$G39/10000*$J39) -> 21.4225 | L39: =ROUNDUP($E$10/$I39,0) -> 5 | M39: =$E$10/$K39 -> 4.6679893 | P39: =IF($N39="","구속 공격(비교 안 함)",IF(AND($L39>=$N39,$L39<=$O39),"목표 안",IF($L39<$N39,"목표보다 아픔","목표보다 약함"))) -> 구속 공격(비교 안 함)
A40: 5016 | B40: {=INDEX(Attack!$C:$C,MATCH($A40,Attack!$A:$A,0))} -> 1006 | C40: {=INDEX(Attack!$B:$B,MATCH($A40,Attack!$A:$A,0))} -> 쇄문아비 문 돌진 | D40: {=INDEX(UnitStat!$G:$G,MATCH($B40,UnitStat!$A:$A,0))} -> 28 | E40: {=INDEX(Attack!$F:$F,MATCH($A40,Attack!$A:$A,0))} -> 15000 | F40: {=INDEX(Attack!$M:$M,MATCH($A40,Attack!$A:$A,0))} -> Y | G40: {=INDEX(UnitStat!$J:$J,MATCH($B40,UnitStat!$A:$A,0))} -> 500 | H40: {=INDEX(UnitStat!$K:$K,MATCH($B40,UnitStat!$A:$A,0))} -> 15000 | I40: =MAX(1,INT($D40*$E40*10000*(10000-$E$11)/10^12+0.000000001)) -> 42 | J40: =MAX(1,INT($D40*$E40*$H40*(10000-$E$11)/10^12+0.000000001)) -> 63 | K40: =(1-IF($F40="Y",$E$12,0)/10000)*((1-$G40/10000)*$I40+$G40/10000*$J40) -> 40.8975 | L40: =ROUNDUP($E$10/$I40,0) -> 3 | M40: =$E$10/$K40 -> 2.4451372 | N40: 3 | O40: 4 | P40: =IF($N40="","구속 공격(비교 안 함)",IF(AND($L40>=$N40,$L40<=$O40),"목표 안",IF($L40<$N40,"목표보다 아픔","목표보다 약함"))) -> 목표 안
A41: 목표는 전투 기획서 C10 기준 체감(잡몹 공격 4~5번, 보스 공격 3~4번에 쓰러짐)에서 가져왔습니다. 구속 공격은 데미지보다 구속 시간이 핵심이라 비교하지 않습니다.
A43: 4. 그래프용 표 (위 값으로 자동 계산)
A44: 4-1. 적 회피율을 바꾸면: 막손이 1타만으로 처치하는 기대 타수
...

Sheet Stage
A1: 규칙 | B1: 한 행 = 스테이지 하나. NextStage는 다음 Stage ID(비면 마지막). 스폰 JSON의 code는 Monster ID. 13행부터의 JSON 예시는 내보내지 않음.
A2: 기능 | B2: 스테이지 순서·BGM·스폰 파일.
A3: 역할 | B3: 스테이지 로더가 읽는다. StageLayer가 이 ID로 매달림.
A4: 의도 | B4: 맵 순서와 배치를 코드 수정 없이 바꾸기 위해.
A5: 비고 | B5: Name, Note
A6: ID | B6: Name | C6: TextID | D6: Order | E6: NextStage | F6: BGM_Normal | G6: BGM_Battle | H6: SpawnFile | I6: Active | J6: Note
A7: 8001 | B7: 마을(도화골) | C7: 30011 | D7: 1 | E7: 8002 | F7: BGM_VILLAGE | G7: BGM_BATTLE | H7: spawn/8001.json | I7: Y | J7: 인트로 컷씬 뒤, 부상당한 피난민 NPC
A8: 8002 | B8: 사냥터 1 | C8: 30012 | D8: 2 | E8: 8003 | F8: BGM_FIELD | G8: BGM_BATTLE | H8: spawn/8002.json | I8: Y
A9: 8003 | B9: 사냥터 2 | C9: 30013 | D9: 3 | E9: 8004 | F9: BGM_FIELD | G9: BGM_BATTLE | H9: spawn/8003.json | I9: Y | J9: 장부방(결박 가르기 해금)
A10: 8004 | B10: 보스방 | C10: 30014 | D10: 4 | G10: BGM_BOSS | H10: spawn/8004.json | I10: Y | J10: 전투 BGM BPM 낮춤 버전(10/28)
A13: 스폰 JSON 예시 (10/28 회의: 몬스터 코드 + count, 위치도 JSON, 초기엔 확률 없음. code = Monster ID)
A14: {"stage":8002,"spawns":[{"code":3001,"count":3,"points":[[1200,0],[1800,0],[2600,0]]},{"code":3002,"count":1,"points":[[3400,0]]}]}
A15: 맵당 몬스터 2종 + 보스 1(지스타 범위). 배치는 제안이며 레벨 디자인에서 확정

Sheet StageLayer
A1: 규칙 | B1: 한 행 = 스테이지의 배경 레이어 하나. StageID는 Stage ID. Parallax는 카메라 이동 대비 만분율(0=고정, 10000=플레이 레이어와 같이).
A2: 기능 | B2: 레이어 순서·이미지·패럴랙스·정렬.
A3: 역할 | B3: 배경 조립기가 StageID로 묶어 읽는다.
A4: 의도 | B4: 배경을 레이어로 조립하고 스테이지별로 바꾸기 위해(10/28 회의).
A5: 비고 | B5: Name, Note
A6: ID | B6: Name | C6: StageID | D6: LayerIndex | E6: LayerName | F6: ImageKey | G6: Parallax | H6: SortOrder | I6: Active | J6: Note
A7: 9001 | B7: 마을 하늘 | C7: 8001 | D7: 0 | E7: 하늘 | F7: BG_8001_SKY | G7: 0 | H7: -40 | I7: Y | J7: 불타는 밤하늘
A8: 9002 | B8: 마을 원경 | C8: 8001 | D8: 1 | E8: 원경 | F8: BG_8001_FAR | G8: 2000 | H8: -30 | I8: Y | J8: 산자락
A9: 9003 | B9: 마을 중경 | C9: 8001 | D9: 2 | E9: 중경 | F9: BG_8001_MID | G9: 5000 | H9: -20 | I9: Y | J9: 불타는 초가
A10: 9004 | B10: 마을 플레이 | C10: 8001 | D10: 3 | E10: 플레이 | F10: BG_8001_PLAY | G10: 10000 | H10: 0 | I10: Y | J10: 밟는 땅
A11: 9005 | B11: 마을 전경 | C11: 8001 | D11: 4 | E11: 전경 | F11: BG_8001_FRONT | G11: 12000 | H11: 10 | I11: Y | J11: 연기·불티
A12: 9006 | B12: 사냥터 1 하늘 | C12: 8002 | D12: 0 | E12: 하늘 | F12: BG_8002_SKY | G12: 0 | H12: -40 | I12: Y
A13: 9007 | B13: 사냥터 1 원경 | C13: 8002 | D13: 1 | E13: 원경 | F13: BG_8002_FAR | G13: 2000 | H13: -30 | I13: Y
A14: 9008 | B14: 사냥터 1 중경 | C14: 8002 | D14: 2 | E14: 중경 | F14: BG_8002_MID | G14: 5000 | H14: -20 | I14: Y
A15: 9009 | B15: 사냥터 1 플레이 | C15: 8002 | D15: 3 | E15: 플레이 | F15: BG_8002_PLAY | G15: 10000 | H15: 0 | I15: Y
A16: 9010 | B16: 사냥터 2 하늘 | C16: 8003 | D16: 0 | E16: 하늘 | F16: BG_8003_SKY | G16: 0 | H16: -40 | I16: Y
A17: 9011 | B17: 사냥터 2 원경 | C17: 8003 | D17: 1 | E17: 원경 | F17: BG_8003_FAR | G17: 2000 | H17: -30 | I17: Y
A18: 9012 | B18: 사냥터 2 중경 | C18: 8003 | D18: 2 | E18: 중경 | F18: BG_8003_MID | G18: 5000 | H18: -20 | I18: Y
A19: 9013 | B19: 사냥터 2 플레이 | C19: 8003 | D19: 3 | E19: 플레이 | F19: BG_8003_PLAY | G19: 10000 | H19: 0 | I19: Y
A20: 9014 | B20: 보스방 배경 | C20: 8004 | D20: 0 | E20: 배경 | F20: BG_8004_BACK | G20: 3000 | H20: -20 | I20: Y | J20: 보스방은 고정 화면에 가까움
A21: 9015 | B21: 보스방 플레이 | C21: 8004 | D21: 1 | E21: 플레이 | F21: BG_8004_PLAY | G21: 10000 | H21: 0 | I21: Y

Sheet State
A1: 규칙 | B1: 한 행 = 상태 하나. Key는 애니메이터 상태 이름(영어, 겹치지 않음). Common Y = 10/28 회의의 공통 상태. Player·Monster·Boss Y = 그 유닛이 씀.
A2: 기능 | B2: 상태 목록과 유닛별 사용 여부.
A3: 역할 | B3: 상태 머신과 Attack.StateID가 이 ID로 가리킨다.
A4: 의도 | B4: 유닛마다 필요한 상태·애니메이션을 한눈에 맞추기 위해.
A5: 비고 | B5: Name, Note
A6: ID | B6: Name | C6: Key | D6: Common | E6: Player | F6: Monster | G6: Boss | H6: Required | I6: Active | J6: Note
A7: 10001 | B7: 아이들 | C7: Idle | D7: Y | E7: Y | F7: Y | G7: Y | H7: Y | I7: Y
A8: 10002 | B8: 워크 | C8: Walk | D8: Y | E8: Y | F8: Y | G8: Y | H8: Y | I8: Y
A9: 10003 | B9: 히트 | C9: Hit | D9: Y | E9: Y | F9: Y | G9: Y | H9: Y | I9: Y | J9: 플레이어 300ms 후 무적 600ms. 슈퍼아머 중엔 생략
A10: 10004 | B10: 어택1 | C10: Attack1 | D10: Y | E10: Y | F10: Y | G10: Y | H10: Y | I10: Y
A11: 10005 | B11: 어택2 | C11: Attack2 | D11: Y | E11: Y | F11: Y | G11: Y | H11: Y | I11: Y | J11: 보스 어택 2-1 수정 예정
A12: 10006 | B12: 어택3 | C12: Attack3 | D12: Y | E12: Y | F12: N | G12: Y | H12: Y | I12: Y
A13: 10007 | B13: 회피 | C13: Evade | D13: Y | E13: Y | F13: Y | G13: Y | H13: Y | I13: Y | J13: 회피 확률 발동 시 모션. 구르기와 별개
A14: 10008 | B14: 크리티컬 히트 | C14: CritHit | D14: Y | E14: Y | F14: Y | G14: Y | H14: Y | I14: Y
A15: 10009 | B15: 스킬1 | C15: Skill1 | D15: Y | E15: Y | F15: Y | G15: Y | H15: Y | I15: Y | J15: 플레이어 = 결박 가르기
A16: 10010 | B16: 매달리기 | C16: Hang | D16: Y | E16: Y | F16: N | G16: N | H16: Y | I16: Y | J16: 10/28 필수. 자동 잡기
A17: 10011 | B17: 착지 | C17: Land | D17: Y | E17: Y | F17: N | G17: N | H17: N | I17: Y | J17: 선택. 5타일 이상 낙하 시 200ms
A18: 10012 | B18: 구르기 | C18: Roll | D18: N | E18: Y | F18: N | G18: N | H18: Y | I18: Y | J18: 조작 회피. 무적 300ms
A19: 10013 | B19: 점프/낙하 | C19: Jump | D19: N | E19: Y | F19: N | G19: N | H19: Y | I19: Y
A20: 10014 | B20: 급소 노출 | C20: Exposed | D20: N | E20: N | F20: Y | G20: Y | H20: Y | I20: Y | J20: 체세 0
A21: 10015 | B21: 해체 | C21: Execute | D21: N | E21: Y | F21: Y | G21: Y | H21: Y | I21: Y | J21: 플레이어는 실행, 대상은 당함
A22: 10016 | B22: 사망 | C22: Dead | D22: N | E22: Y | F22: Y | G22: Y | H22: Y | I22: Y
A23: 10017 | B23: 약초 사용 | C23: Heal | D23: N | E23: Y | F23: N | G23: N | H23: Y | I23: Y | J23: 800ms
A24: 10018 | B24: 무기 획득 | C24: Acquire | D24: N | E24: Y | F24: N | G24: N | H24: N | I24: Y | J24: 무기별 획득 모션(완성판 위주)

Sheet String
A1: 규칙 | B1: 한 행 = 화면에 보이는 문구 하나. 다른 시트는 TextID(이 ID)로만 가리킨다. KO 우선, EN은 예비.
A2: 기능 | B2: 표시 텍스트.
A3: 역할 | B3: UI와 이름 표시가 읽는다.
A4: 의도 | B4: 문구와 번역을 코드 수정 없이 바꾸기 위해.
A5: 비고 | B5: Name, Note
A6: ID | B6: Name | C6: KO | D6: EN | E6: Active | F6: Note
A7: 30001 | B7: 막손 이름 | C7: 막손 | E7: Y | F7: 주인공
A8: 30002 | B8: 허수귀 이름 | C8: 허수귀 | E8: Y
A9: 30003 | B9: 지게귀 이름 | C9: 지게귀 | E9: Y
A10: 30004 | B10: 불붙은 허수귀 이름 | C10: 불붙은 허수귀 | E10: Y | F10: 변종
A11: 30005 | B11: 짐 던지는 지게귀 이름 | C11: 짐 던지는 지게귀 | E11: Y | F11: 변종
A12: 30006 | B12: 쇄문아비 이름 | C12: 쇄문아비 | E12: Y | F12: 보스
A13: 30007 | B13: 발골칼 이름 | C13: 발골칼 | E13: Y
A14: 30008 | B14: 버선칼 이름 | C14: 버선칼 | E14: Y | F14: 완성판
A15: 30009 | B15: 쇠메 이름 | C15: 쇠메 | E15: Y | F15: 완성판
A16: 30010 | B16: 결박 가르기 스킬 이름 | C16: 결박 가르기 | E16: Y
A17: 30011 | B17: 마을 이름 | C17: 도화골 | E17: Y
A18: 30012 | B18: 사냥터 1 이름 | C18: 사냥터 1 | E18: Y | F18: 이름 미정
A19: 30013 | B19: 사냥터 2 이름 | C19: 사냥터 2 | E19: Y | F19: 이름 미정
A20: 30014 | B20: 보스방 이름 | C20: 보스방 | E20: Y | F20: 이름 미정
A21: 30015 | B21: 발골칼 1타 | C21: 베기 | E21: Y
A22: 30016 | B22: 발골칼 2타 | C22: 베기 | E22: Y
A23: 30017 | B23: 발골칼 3타 | C23: 내리베기 | E23: Y
A24: 30018 | B24: 공중 1타 | C24: 공중 베기 | E24: Y
A25: 30019 | B25: 해체 | C25: 해체 | E25: Y
A26: 30020 | B26: 결박 가르기 공격 | C26: 결박 가르기 | E26: Y
A27: 30021 | B27: 회피 발동 표시 | C27: 회피 | E27: Y | F27: 회피 확률 발동 시 표시
A28: 30022 | B28: 약초 | C28: 약초 | E28: Y
A29: 30023 | B29: 스킬 해금 알림 | C29: 결박 가르기를 익혔다 | E29: Y | F29: 장부방
A30: 30024 | B30: 저장 알림 | C30: 기록했다 | E30: Y | F30: 저장 지점
A31: 30025 | B31: 마지막 컷씬 | C31: TO BE CONTINUED | E31: Y
A32: 30026 | B32: 로딩 | C32: 불러오는 중 | E32: Y | F32: 로딩씬
